{
	"title": "Python3 错误和异常 | 菜鸟教程",
	"url": "https://www.runoob.com/python3/python3-errors-execptions.html",
	"html": "菜鸟教程 -- 学的不仅是技术，更是梦想！\n首页 HTML CSS JAVASCRIPT VUE BOOTSTRAP NODEJS PYTHON3 PYTHON2 JAVA C C++ C# GO SQL LINUX JQUERY 本地书签\n Python 3 教程 \nPython3 教程\nPython3 简介\nPython3 环境搭建\nPython3 VScode\nPython3 基础语法\nPython3 基本数据类型\nPython3 数据类型转换\nPython3 解释器\nPython3 注释\nPython3 运算符\nPython3 数字(Number)\nPython3 字符串\nPython3 列表\nPython3 元组\nPython3 字典\nPython3 集合\nPython3 条件控制\nPython3 循环语句\nPython3 编程第一步\nPython3 推导式\nPython3 迭代器与生成器\nPython3 函数\nPython3 lambda\nPython3 数据结构\nPython3 模块\nPython3 输入和输出\nPython3 File\nPython3 OS\n Python3 错误和异常\nPython3 面向对象\nPython3 命名空间/作用域\nPython3 标准库概览\nPython3 实例\nPython 测验\n\n\nPython3 高级教程\nPython3 正则表达式\nPython3 CGI编程\nPython3 MySQL(mysql-connector)\nPython3 MySQL(PyMySQL)\nPython3 网络编程\nPython3 SMTP发送邮件\nPython3 多线程\nPython3 XML 解析\nPython3 JSON\nPython3 日期和时间\nPython3 内置函数\nPython3 MongoDB\nPython3 urllib\nPython uWSGI 安装配置\nPython3 pip\nPython3 operator\nPython math\nPython requests\nPython random\nPython 有用的资源\nPython AI 绘画\nPython statistics\n Python3 OS\nPython3 面向对象 \nPython3 错误和异常\n\n作为 Python 初学者，在刚学习 Python 编程时，经常会看到一些报错信息，在前面我们没有提及，这章节我们会专门介绍。\n\nPython 有两种错误很容易辨认：语法错误和异常。\n\nPython assert（断言）用于判断一个表达式，在表达式条件为 false 的时候触发异常。\n\n语法错误\n\nPython 的语法错误或者称之为解析错，是初学者经常碰到的，如下实例\n\n>>> while True print('Hello world')\n  File \"<stdin>\", line 1, in ?\n    while True print('Hello world')\n                   ^\nSyntaxError: invalid syntax\n\n\n这个例子中，函数 print() 被检查到有错误，是它前面缺少了一个冒号 : 。\n\n语法分析器指出了出错的一行，并且在最先找到的错误的位置标记了一个小小的箭头。\n\n异常\n\n即便 Python 程序的语法是正确的，在运行它的时候，也有可能发生错误。运行期检测到的错误被称为异常。\n\n大多数的异常都不会被程序处理，都以错误信息的形式展现在这里:\n\n实例\n>>> 10 * (1/0)             # 0 不能作为除数，触发异常\nTraceback (most recent call last):\n  File \"<stdin>\", line 1, in ?\nZeroDivisionError: division by zero\n>>> 4 + spam*3             # spam 未定义，触发异常\nTraceback (most recent call last):\n  File \"<stdin>\", line 1, in ?\nNameError: name 'spam' is not defined\n>>> '2' + 2               # int 不能与 str 相加，触发异常\nTraceback (most recent call last):\n  File \"<stdin>\", line 1, in <module>\nTypeError: can only concatenate str (not \"int\") to str\n\n\n异常以不同的类型出现，这些类型都作为信息的一部分打印出来: 例子中的类型有 ZeroDivisionError，NameError 和 TypeError。\n\n错误信息的前面部分显示了异常发生的上下文，并以调用栈的形式显示具体信息。\n\n异常处理\ntry/except\n\n异常捕捉可以使用 try/except 语句。\n\n以下例子中，让用户输入一个合法的整数，但是允许用户中断这个程序（使用 Control-C 或者操作系统提供的方法）。用户中断的信息会引发一个 KeyboardInterrupt 异常。\n\nwhile True:\n    try:\n        x = int(input(\"请输入一个数字: \"))\n        break\n    except ValueError:\n        print(\"您输入的不是数字，请再次尝试输入！\")\n\n\ntry 语句按照如下方式工作；\n\n首先，执行 try 子句（在关键字 try 和关键字 except 之间的语句）。\n\n如果没有异常发生，忽略 except 子句，try 子句执行后结束。\n\n如果在执行 try 子句的过程中发生了异常，那么 try 子句余下的部分将被忽略。如果异常的类型和 except 之后的名称相符，那么对应的 except 子句将被执行。\n\n如果一个异常没有与任何的 except 匹配，那么这个异常将会传递给上层的 try 中。\n\n一个 try 语句可能包含多个except子句，分别来处理不同的特定的异常。最多只有一个分支会被执行。\n\n处理程序将只针对对应的 try 子句中的异常进行处理，而不是其他的 try 的处理程序中的异常。\n\n一个except子句可以同时处理多个异常，这些异常将被放在一个括号里成为一个元组，例如:\n\nexcept (RuntimeError, TypeError, NameError):\n    pass\n\n\n最后一个except子句可以忽略异常的名称，它将被当作通配符使用。你可以使用这种方法打印一个错误信息，然后再次把异常抛出。\n\nimport sys\n\ntry:\n    f = open('myfile.txt')\n    s = f.readline()\n    i = int(s.strip())\nexcept OSError as err:\n    print(\"OS error: {0}\".format(err))\nexcept ValueError:\n    print(\"Could not convert data to an integer.\")\nexcept:\n    print(\"Unexpected error:\", sys.exc_info()[0])\n    raise\n\ntry/except...else\n\ntry/except 语句还有一个可选的 else 子句，如果使用这个子句，那么必须放在所有的 except 子句之后。\n\nelse 子句将在 try 子句没有发生任何异常的时候执行。\n\n以下实例在 try 语句中判断文件是否可以打开，如果打开文件时正常的没有发生异常则执行 else 部分的语句，读取文件内容：\n\nfor arg in sys.argv[1:]:\n    try:\n        f = open(arg, 'r')\n    except IOError:\n        print('cannot open', arg)\n    else:\n        print(arg, 'has', len(f.readlines()), 'lines')\n        f.close()\n\n\n使用 else 子句比把所有的语句都放在 try 子句里面要好，这样可以避免一些意想不到，而 except 又无法捕获的异常。\n\n异常处理并不仅仅处理那些直接发生在 try 子句中的异常，而且还能处理子句中调用的函数（甚至间接调用的函数）里抛出的异常。例如:\n\n>>> def this_fails():\n        x = 1/0\n   \n>>> try:\n        this_fails()\n    except ZeroDivisionError as err:\n        print('Handling run-time error:', err)\n   \nHandling run-time error: int division or modulo by zero\n\ntry-finally 语句\n\ntry-finally 语句无论是否发生异常都将执行最后的代码。\n\n以下实例中 finally 语句无论异常是否发生都会执行：\n\n实例\ntry:\n    runoob()\nexcept AssertionError as error:\n    print(error)\nelse:\n    try:\n        with open('file.log') as file:\n            read_data = file.read()\n    except FileNotFoundError as fnf_error:\n        print(fnf_error)\nfinally:\n    print('这句话，无论异常是否发生都会执行。')\n\n抛出异常\n\nPython 使用 raise 语句抛出一个指定的异常。\n\nraise语法格式如下：\n\nraise [Exception [, args [, traceback]]]\n\n以下实例如果 x 大于 5 就触发异常:\n\nx = 10\nif x > 5:\n    raise Exception('x 不能大于 5。x 的值为: {}'.format(x))\n\n\n执行以上代码会触发异常：\n\nTraceback (most recent call last):\n  File \"test.py\", line 3, in <module>\n    raise Exception('x 不能大于 5。x 的值为: {}'.format(x))\nException: x 不能大于 5。x 的值为: 10\n\nraise 唯一的一个参数指定了要被抛出的异常。它必须是一个异常的实例或者是异常的类（也就是 Exception 的子类）。\n\n如果你只想知道这是否抛出了一个异常，并不想去处理它，那么一个简单的 raise 语句就可以再次把它抛出。\n\n>>> try:\n        raise NameError('HiThere')  # 模拟一个异常。\n    except NameError:\n        print('An exception flew by!')\n        raise\n   \nAn exception flew by!\nTraceback (most recent call last):\n  File \"<stdin>\", line 2, in ?\nNameError: HiThere\n\n用户自定义异常\n\n你可以通过创建一个新的异常类来拥有自己的异常。异常类继承自 Exception 类，可以直接继承，或者间接继承，例如:\n\n>>> class MyError(Exception):\n        def __init__(self, value):\n            self.value = value\n        def __str__(self):\n            return repr(self.value)\n   \n>>> try:\n        raise MyError(2*2)\n    except MyError as e:\n        print('My exception occurred, value:', e.value)\n   \nMy exception occurred, value: 4\n>>> raise MyError('oops!')\nTraceback (most recent call last):\n  File \"<stdin>\", line 1, in ?\n__main__.MyError: 'oops!'\n\n\n在这个例子中，类 Exception 默认的 __init__() 被覆盖。\n\n当创建一个模块有可能抛出多种不同的异常时，一种通常的做法是为这个包建立一个基础异常类，然后基于这个基础类为不同的错误情况创建不同的子类:\n\nclass Error(Exception):\n    \"\"\"Base class for exceptions in this module.\"\"\"\n    pass\n\nclass InputError(Error):\n    \"\"\"Exception raised for errors in the input.\n\n    Attributes:\n        expression -- input expression in which the error occurred\n        message -- explanation of the error\n    \"\"\"\n\n    def __init__(self, expression, message):\n        self.expression = expression\n        self.message = message\n\nclass TransitionError(Error):\n    \"\"\"Raised when an operation attempts a state transition that's not\n    allowed.\n\n    Attributes:\n        previous -- state at beginning of transition\n        next -- attempted new state\n        message -- explanation of why the specific transition is not allowed\n    \"\"\"\n\n    def __init__(self, previous, next, message):\n        self.previous = previous\n        self.next = next\n        self.message = message\n\n\n大多数的异常的名字都以\"Error\"结尾，就跟标准的异常命名一样。\n\n定义清理行为\n\ntry 语句还有另外一个可选的子句，它定义了无论在任何情况下都会执行的清理行为。 例如:\n\n>>> try:\n...     raise KeyboardInterrupt\n... finally:\n...     print('Goodbye, world!')\n...\nGoodbye, world!\nTraceback (most recent call last):\n  File \"<stdin>\", line 2, in <module>\nKeyboardInterrupt\n\n\n以上例子不管 try 子句里面有没有发生异常，finally 子句都会执行。\n\n如果一个异常在 try 子句里（或者在 except 和 else 子句里）被抛出，而又没有任何的 except 把它截住，那么这个异常会在 finally 子句执行后被抛出。\n\n下面是一个更加复杂的例子（在同一个 try 语句里包含 except 和 finally 子句）:\n\n>>> def divide(x, y):\n        try:\n            result = x / y\n        except ZeroDivisionError:\n            print(\"division by zero!\")\n        else:\n            print(\"result is\", result)\n        finally:\n            print(\"executing finally clause\")\n   \n>>> divide(2, 1)\nresult is 2.0\nexecuting finally clause\n>>> divide(2, 0)\ndivision by zero!\nexecuting finally clause\n>>> divide(\"2\", \"1\")\nexecuting finally clause\nTraceback (most recent call last):\n  File \"<stdin>\", line 1, in ?\n  File \"<stdin>\", line 3, in divide\nTypeError: unsupported operand type(s) for /: 'str' and 'str'\n\n预定义的清理行为\n\n一些对象定义了标准的清理行为，无论系统是否成功的使用了它，一旦不需要它了，那么这个标准的清理行为就会执行。\n\n下面这个例子展示了尝试打开一个文件，然后把内容打印到屏幕上:\n\nfor line in open(\"myfile.txt\"):\n    print(line, end=\"\")\n\n\n以上这段代码的问题是，当执行完毕后，文件会保持打开状态，并没有被关闭。\n\n关键词 with 语句就可以保证诸如文件之类的对象在使用完之后一定会正确的执行他的清理方法:\n\nwith open(\"myfile.txt\") as f:\n    for line in f:\n        print(line, end=\"\")\n\n\n以上这段代码执行完毕后，就算在处理过程中出问题了，文件 f 总是会关闭。\n\n更多 with 关键字内容参考：Python with 关键字\n\n相关内容\n\nPython assert（断言）\n\nPython with 关键字\n\n Python3 OS\nPython3 面向对象 \n6 篇笔记\n 写笔记\n 分类导航\nHTML / CSS\nJavaScript\n服务端\n数据库\n数据分析\n移动端\nXML 教程\nASP.NET\nWeb Service\n开发工具\n网站建设\n\n\nAdvertisement\n反馈/建议\n反馈/建议\n在线实例\n·HTML 实例\n·CSS 实例\n·JavaScript 实例\n·Ajax 实例\n·jQuery 实例\n·XML 实例\n·Java 实例\n字符集&工具\n· HTML 字符集设置\n· HTML ASCII 字符集\n· JS 混淆/加密\n· PNG/JPEG 图片压缩\n· HTML 拾色器\n· JSON 格式化工具\n· 随机数生成器\n最新更新\n· 正则表达式入门教程\n· Python lambda（...\n· Java 注释\n· Bootstrap5 消息...\n· Python 按字母顺...\n· Python 删除字符...\n· git restore 命令\n站点信息\n· 意见反馈\n· 免责声明\n· 关于我们\n· 文章归档\n关注微信\nCopyright © 2013-2023 菜鸟教程  runoob.com All Rights Reserved. 备案号：闽ICP备15012807号-1\n  \nRUNOOB asks for your consent to use your personal data to:\nperm_identity\nPersonalised advertising and content, advertising and content measurement, audience research and services development\ndevices\nStore and/or access information on a device\nexpand_more\nLearn more\n\nYour personal data will be processed and information from your device (cookies, unique identifiers, and other device data) may be stored by, accessed by and shared with 136 TCF vendor(s) and 66 ad partner(s), or used specifically by this site or app.\n\nSome vendors may process your personal data on the basis of legitimate interest, which you can object to by managing your options below. Look for a link at the bottom of this page or in our privacy policy where you can withdraw consent.\n\nConsent\n\nDo not consent\n\nManage options"
}